Workbook

Sheet Req Init 1.1
A1: Kellanova POC | B1: all fields we need are on pgs 23-30 of NIF Training Deck
A3: Sections | B3: fields | C3: field type | D3: rules | F3: drop down/list of values
F4: Country that owns new item being created | G4: data repeated | H4: data repeated | I4: NIF KEY abbreviation nomenclature
A5: Product Setup | F5: Product Country | G5: Form Type | H5: Product Type | I5: Product Sub Type | J5: Project Type
B6: Business Area | C6: drop down | D6: "Kellanova" | F6: US - United States | G6: Case | H6: Bulk Case | I6: BULK CS, NO PKG UPC | J6: KUBIC
B7: Form Type | C7: drop down | F7: CA - Canada | G7: Case | H7: Bulk Case | I7: BULK CS, PKG | J7: PDR
B8: Product Country | C8: drop down | F8: MX - Mexico | G8: Case | H8: Bulk Case | I8: BULK CS, PKG RPK/RCP | J8: PWR
B9: Product Type | C9: drop down | G9: Case | H9: Canada Bulk Case | I9: CA BULK CS, PKG | J9: SCR
B10: Product Sub Type | C10: drop down | G10: Case | H10: Canada Bulk Case | I10: CA BULK CS, NO PKG UPC
B11: Is this a Pringle product? | C11: drop down | D11: yes/no | G11: Case | H11: Canada Club | I11: CA CLUB, TRADITIONAL
B12: Is this an RX product? | C12: drop down | D12: yes/no | G12: Case | H12: Canada Club | I12: CA CLUB, UL
B13: SAP Material Number | C13: not enterable | G13: Case | H13: Canada Straight Case | I13: CA CS, PKG
B14: Project Type | C14: drop down | G14: Case | H14: Canada Straight Case | I14: CA CS, PKG & PCH/INNER
B15: Project Name or Number | C15: free form | G15: Case | H15: Canada Straight Case Repack/RCP - existing PKG UPC | I15: CA CS, PKG RPK/RCP
B16: Set Category | C16: not enterable | D16: maybe filled in by Material Prefix answer (further down) | G16: Case | H16: Canada Straight Case Repack/RCP - existing PKG UPC | I16: CA CS, PKG & PCH/INNER RPK/RCP
B17: Brief Product Description | C17: free form | G17: Case | H17: Canada Straight Case Repack/RCP - new PKG UPC | I17: CA CS, PKG RPK/RCP
B18: Brief Project Overview | C18: free form | G18: Case | H18: Canada Straight Case Repack/RCP - new PKG UPC | I18: CA CS, PKG & PCH/INNER RPK/RCP
G19: Case | H19: Canada WIP Case | I19: CA WIP, CASE (HALB)
G20: Case | H20: Canada WIP Tote | I20: CA WIP, TOTE (HALB)
G21: Case | H21: Club | I21: CLUB, NON-TRADITIONAL
G22: Case | H22: Club | I22: CLUB, TRADITIONAL
G23: Case | H23: Club Repack/RCP | I23: CLUB, NON-TRADITIONAL RPK/RCP
G24: Case | H24: Club Repack/RCP | I24: CLUB, TRADITIONAL RPK/RCP
G25: Case | H25: DTC Bundle | I25: DTC
G26: Case | H26: EComm | I26: ECOMM CASE
G27: Case | H27: EComm | I27: ECOMM PACKAGE
G28: Display | H28: Full Mod | I28: DISPLAY, FULL MOD
G29: Display | H29: Half Mod | I29: DISPLAY, HALF MOD
G30: Display | H30: Qtr Mod | I30: DISPLAY, QTR MOD
... G39: WIP | H39: WIP Tote | I39: WIP, TOTE (HALB)
A44: Stated Weights/Case Count
B45: Stated Weight Applicable For | C45: drop down | F45: Stated Weight Applicable For | G45: Stated Weight Status | H45: Stated Net Weight UOM | I45: Case Count Status
B46: Stated Weight Status | C46: drop down | F46: Package | G46: Estimated | H46: OZ | I46: Estimated
B47: Stated Net Weight | C47: number | F47: Inner Item/Pouch | G47: Finalized | H47: G | I47: Finalized
B48: Stated Net Weight UOM | C48: drop down
B49: Case Count Status | C49: drop down
B50: Case Count | C50: number
A53: Reference Material
B54: Like SKU / Reference Material Number | C54: drop down | D54: references SAP db
A56: Product Determination Questions - Case | F56: Designated Customer Name
...

Sheet All sections of NIF PDF
A1: Review of NIF Training Deck - Bev Tyler | G1: dd = drop downs | K1: BR.xlsx file = https://demandchainai.sharepoint.com/:x:/s/KellanovaPOC/Ebpe4JJnLcJDsKN74E_FN2oBGy3SMnB3ieLdjMvL_nwzIge=VenuuF | V1: Complexity: | W1: 3 | X1: 2 | Y1: 1 | Z1: 0
G2: PRL=PRODUCT_REFERENCE_LIST.XLSX | K2: Trng_deck.ppt = https://demandchainai.sharepoint.com/:b:/s/KellanovaPOC/EUbYiN0y3vRHupu27Q5q6Q8BBsRldO5V1fX6na9le0eAuAe=crBJEK | V2: Hours: | W2: 1.5 | X2: 1 | Y2: 0.5 | Z2: 0
A3: UNIQUE FIELD # (order in Trng deck) | B3: Training Section | C3: section name | D3: field names in Trng deck | E3: #fields enterable in Trng deck | F3: page(s) of Trng deck | G3: types of fields | H3: required | I3: owner | J3: additional roles who can modify | K3: column referenced in BR.xlsx file (from Tamara) | L3: comments | M3: Business Rules (technical) | N3: Business Rules (AI ready) | O3: Business Rule status | P3: Timing status | Q3: Trng Sectn # | R3: Trng Sectn Priority | S3: Week | T3: Week Beginning Date | U3: PRIORITY (1..9) 1-highest 5-mid 9-lowest | V3: COMPLEXITY (3..1,0) 3-high 2-med 1-low 0-autofill | W3: Hours | X3: Sprint | Y3: Date: Field Last Reviewed for Business Rules | Z3: Date: Expert System Rules updated (Excel) | AA3: Date: Handed off to AI BOT team (Justin)
A4: 1001 | B4: Requestor - Project Initiation | C4: Requestor Initiate | D4: Requestor Name | E4: 0 | F4: 23 | G4: autofill | H4: yes | I4: Requestor | M4: pull name from user logged in | O4: done | P4: complete | Q4: =VLOOKUP(B4,LOV!$B:$C,2,FALSE) -> 10 | R4: =VLOOKUP(B4,LOV!$B:$D,3,FALSE) -> AA | S4: =VLOOKUP($X4,LOV!$F:$L,2,FALSE) -> WK2 | T4: =VLOOKUP($X4,LOV!$F:$L,7,FALSE) -> 45922 | U4: 9 | V4: 0 | W4: =IF(ISNUMBER(V4),HLOOKUP(V4,$V$1:$AA$2,2,FALSE)*E4,"") -> 0 | X4: E | Y4: 45923 | Z4: 45925 | AA4: 45929
A5: 1002 | B5: Requestor - Project Initiation | C5: Requestor Initiate | D5: Requestor Email | E5: 0 | F5: 23 | G5: autofill | H5: yes | I5: Requestor | M5: pull email from user logged in | O5: done | P5: complete | Q5: =VLOOKUP(B5,LOV!$B:$C,2,FALSE) -> 10 | R5: =VLOOKUP(B5,LOV!$B:$D,3,FALSE) -> AA | S5: =VLOOKUP($X5,LOV!$F:$L,2,FALSE) -> WK2 | T5: =VLOOKUP($X5,LOV!$F:$L,7,FALSE) -> 45922 | U5: 9 | V5: 0 | W5: =IF(ISNUMBER(V5),HLOOKUP(V5,$V$1:$AA$2,2,FALSE)*E5,"") -> 0 | X5: E | Y5: 45923 | Z5: 45925 | AA5: 45929
A6: 1003 | B6: Requestor - Project Initiation | C6: Requestor Initiate | D6: Requestor Date | E6: 0 | F6: 23 | G6: autofill | H6: yes | I6: Requestor | M6: pull date from computer | O6: done | P6: complete | Q6: =VLOOKUP(B6,LOV!$B:$C,2,FALSE) -> 10 | R6: =VLOOKUP(B6,LOV!$B:$D,3,FALSE) -> AA | S6: =VLOOKUP($X6,LOV!$F:$L,2,FALSE) -> WK2 | T6: =VLOOKUP($X6,LOV!$F:$L,7,FALSE) -> 45922 | U6: 9 | V6: 0 | W6: =IF(ISNUMBER(V6),HLOOKUP(V6,$V$1:$AA$2,2,FALSE)*E6,"") -> 0 | X6: E | Y6: 45923 | Z6: 45925 | AA6: 45929
A7: 1004 | B7: Requestor - Project Initiation | C7: Requestor Initiate | D7: Version | E7: 0 | F7: 23 | G7: autofill | H7: yes | I7: Requestor | M7: pull NIF version of the form | O7: done | P7: complete | Q7: =VLOOKUP(B7,LOV!$B:$C,2,FALSE) -> 10 | R7: =VLOOKUP(B7,LOV!$B:$D,3,FALSE) -> AA | S7: =VLOOKUP($X7,LOV!$F:$L,2,FALSE) -> WK2 | T7: =VLOOKUP($X7,LOV!$F:$L,7,FALSE) -> 45922 | U7: 9 | V7: 0 | W7: =IF(ISNUMBER(V7),HLOOKUP(V7,$V$1:$AA$2,2,FALSE)*E7,"") -> 0 | X7: E | Y7: 45923 | Z7: 45925 | AA7: 45929
A8: 1005 | B8: Requestor - Project Initiation | C8: Person Responsible | D8: Requestor | E8: 0 | F8: 23 | G8: dd: user roles | H8: yes | I8: Requestor | M8: pull name from user logged in | O8: done | P8: complete | Q8: =VLOOKUP(B8,LOV!$B:$C,2,FALSE) -> 10 | R8: =VLOOKUP(B8,LOV!$B:$D,3,FALSE) -> AA | S8: =VLOOKUP($X8,LOV!$F:$L,2,FALSE) -> WK2 | T8: =VLOOKUP($X8,LOV!$F:$L,7,FALSE) -> 45922 | U8: 9 | V8: 0 | W8: =IF(ISNUMBER(V8),HLOOKUP(V8,$V$1:$AA$2,2,FALSE)*E8,"") -> 0 | X8: E | Y8: 45923 | Z8: 45925 | AA8: 45929
A9: 1006 | B9: Requestor - Project Initiation | C9: Person Responsible | D9: LIM | E9: 1 | F9: 23, 32, 61 | G9: dd: reference list: PRL: LIM_Users | H9: yes | I9: Requestor | J9: LIM | M9: no Business Rules | O9: done | P9: complete | Q9: =VLOOKUP(B9,LOV!$B:$C,2,FALSE) -> 10 | R9: =VLOOKUP(B9,LOV!$B:$D,3,FALSE) -> AA | S9: =VLOOKUP($X9,LOV!$F:$L,2,FALSE) -> WK2 | T9: =VLOOKUP($X9,LOV!$F:$L,7,FALSE) -> 45922 | U9: 4 | V9: 1 | W9: =IF(ISNUMBER(V9),HLOOKUP(V9,$V$1:$AA$2,2,FALSE)*E9,"") -> 0.5 | X9: D | Y9: 45923 | Z9: 45925 | AA9: 45929
A10: 1305 | B10: Requestor - Project Initiation | C10: Product Setup | D10: Business Area | E10: 0 | F10: 0 | G10: dd: WKKC, KELLANOVA | H10: yes | I10: Requestor | L10: 9/24/25 new field identified | M10: autofill to KELLANOVA | O10: done | P10: complete | Q10: =VLOOKUP(B10,LOV!$B:$C,2,FALSE) -> 10 | R10: =VLOOKUP(B10,LOV!$B:$D,3,FALSE) -> AA | S10: =VLOOKUP($X10,LOV!$F:$L,2,FALSE) -> WK2 | T10: =VLOOKUP($X10,LOV!$F:$L,7,FALSE) -> 45922 | V10: 1 | W10: =IF(ISNUMBER(V10),HLOOKUP(V10,$V$1:$AA$2,2,FALSE)*E10,"") -> 0 | X10: E | Y10: 45924 | Z10: 45925 | AA10: 45929
A11: 1007 | B11: Requestor - Project Initiation | C11: Product Setup | D11: Form Type | E11: 1 | F11: 24 | G11: dd: CASE, DISPLAY, WIP | H11: yes | I11: Requestor | K11: col A | M11: Flowchart: Product Type / Product Sub Type | N11: Reliant on Product Country | O11: done | P11: complete | Q11: =VLOOKUP(B11,LOV!$B:$C,2,FALSE) -> 10 | R11: =VLOOKUP(B11,LOV!$B:$D,3,FALSE) -> AA | S11: =VLOOKUP($X11,LOV!$F:$L,2,FALSE) -> WK1 | T11: =VLOOKUP($X11,LOV!$F:$L,7,FALSE) -> 45916 | U11: 1 | V11: 3 | W11: =IF(ISNUMBER(V11),HLOOKUP(V11,$V$1:$AA$2,2,FALSE)*E11,"") -> 1.5 | X11: A | Y11: 45918 | Z11: 45921 | AA11: 45922
A12: 1008 | B12: Requestor - Project Initiation | C12: Product Setup | D12: Product Country | E12: 1 | F12: 24 | G12: dd: reference list: PRODUCT_COUNTRY.XLSX | H12: yes | I12: Requestor | K12: NOT in BR.xlsx | M12: Flowchart: Product Type / Product Sub Type | O12: done | P12: complete | Q12: =VLOOKUP(B12,LOV!$B:$C,2,FALSE) -> 10 | R12: =VLOOKUP(B12,LOV!$B:$D,3,FALSE) -> AA | S12: =VLOOKUP($X12,LOV!$F:$L,2,FALSE) -> WK1 | T12: =VLOOKUP($X12,LOV!$F:$L,7,FALSE) -> 45916 | U12: 1 | V12: 3 | W12: =IF(ISNUMBER(V12),HLOOKUP(V12,$V$1:$AA$2,2,FALSE)*E12,"") -> 1.5 | X12: A | Y12: 45918 | Z12: 45921 | AA12: 45922
A13: 1009 | B13: Requestor - Project Initiation | C13: Product Setup | D13: Product Type | E13: 1 | F13: 24 | G13: dd: reference list: PRODUCT_SETUP_TYPE.XLSX, Setup_Type column | H13: yes | I13: Requestor | K13: col B | L13: dependent on FORM TYPE | M13: Flowchart: Product Type / Product Sub Type | N13: Reliant on Product Country / Form Type | O13: done | P13: complete | Q13: =VLOOKUP(B13,LOV!$B:$C,2,FALSE) -> 10 | R13: =VLOOKUP(B13,LOV!$B:$D,3,FALSE) -> AA | S13: =VLOOKUP($X13,LOV!$F:$L,2,FALSE) -> WK1 | T13: =VLOOKUP($X13,LOV!$F:$L,7,FALSE) -> 45916 | U13: 1 | V13: 3 | W13: =IF(ISNUMBER(V13),HLOOKUP(V13,$V$1:$AA$2,2,FALSE)*E13,"") -> 1.5 | X13: A | Y13: 45924 | Z13: 45924 | AA13: 45929
A14: 1010 | B14: Requestor - Project Initiation | C14: Product Setup | D14: Product Sub Type | E14: 1 | F14: 24 | G14: dd: reference list: PRODUCT_SETUP_TYPE.XLSX, Setup_Qualifier column | H14: yes | I14: Requestor | K14: col C | L14: dependent on PRODUCT TYPE | M14: Flowchart: Product Type / Product Sub Type | N14: Reliant on Product Country / Form Type / Product Type | O14: done | P14: complete | Q14: =VLOOKUP(B14,LOV!$B:$C,2,FALSE) -> 10 | R14: =VLOOKUP(B14,LOV!$B:$D,3,FALSE) -> AA | S14: =VLOOKUP($X14,LOV!$F:$L,2,FALSE) -> WK1 | T14: =VLOOKUP($X14,LOV!$F:$L,7,FALSE) -> 45916 | U14: 1 | V14: 3 | W14: =IF(ISNUMBER(V14),HLOOKUP(V14,$V$1:$AA$2,2,FALSE)*E14,"") -> 1.5 | X14: A | Y14: 45918 | Z14: 45921 | AA14: 45922
A15: 1011 | B15: Requestor - Project Initiation | C15: Product Setup | D15: Is this a Pringles product | E15: 1 | F15: 24 | G15: dd: YES, NO | H15: yes | I15: Requestor | K15: NOT in BR.xlsx | M15: 1011 predecessor for pringles naming convention for country sold in as part of description (1175); plus Pringles Can Size (1235), and RTEC/Pringles Cube Size (1239) is required | O15: done | P15: complete | Q15: =VLOOKUP(B15,LOV!$B:$C,2,FALSE) -> 10 | R15: =VLOOKUP(B15,LOV!$B:$D,3,FALSE) -> AA | S15: =VLOOKUP($X15,LOV!$F:$L,2,FALSE) -> WK1 | T15: =VLOOKUP($X15,LOV!$F:$L,7,FALSE) -> 45916 | U15: 1 | V15: 1 | W15: =IF(ISNUMBER(V15),HLOOKUP(V15,$V$1:$AA$2,2,FALSE)*E15,"") -> 0.5 | X15: A | Y15: 45919 | Z15: 45923 | AA15: 45923
A16: 1012 | B16: Requestor - Project Initiation | C16: Product Setup | D16: Is this an RX Product | E16: 1 | F16: 24 | G16: dd: YES, NO | H16: yes | I16: Requestor | K16: NOT in BR.xlsx | M16: 1012 predecessor to: "Will product be sold DTC question" (1162), this will also kick off the DTC form at end of process; Dependencies 1292, 1301, 1302 | O16: done | P16: complete | Q16: =VLOOKUP(B16,LOV!$B:$C,2,FALSE) -> 10 | R16: =VLOOKUP(B16,LOV!$B:$D,3,FALSE) -> AA | S16: =VLOOKUP($X16,LOV!$F:$L,2,FALSE) -> WK1 | T16: =VLOOKUP($X16,LOV!$F:$L,7,FALSE) -> 45916 | U16: 1 | V16: 1 | W16: =IF(ISNUMBER(V16),HLOOKUP(V16,$V$1:$AA$2,2,FALSE)*E16,"") -> 0.5 | X16: A | Y16: 45919 | Z16: 45923 | AA16: 45923
A17: 1013 | B17: Requestor - Project Initiation | C17: Product Setup | D17: SAP Material Number | E17: 0 | F17: 24, 45 | G17: free form | H17: no | I17: Masterfiles | L17: same as field 1070 | M17: duplicate of 1070 | N17: (same as Material Number) | O17: done | P17: complete | Q17: =VLOOKUP(B17,LOV!$B:$C,2,FALSE) -> 10 | R17: =VLOOKUP(B17,LOV!$B:$D,3,FALSE) -> AA | S17: =VLOOKUP($X17,LOV!$F:$L,2,FALSE) -> WK1 | T17: =VLOOKUP($X17,LOV!$F:$L,7,FALSE) -> 45916 | U17: 1 | V17: 1 | W17: =IF(ISNUMBER(V17),HLOOKUP(V17,$V$1:$AA$2,2,FALSE)*E17,"") -> 0 | X17: B | Y17: 45919 | Z17: 45919 | AA17: 45919
A18: 1014 | B18: Requestor - Project Initiation | C18: Product Setup | D18: Project Type | E18: 1 | F18: 24 | G18: dd: KUBIC, PDR, PWR, SCR | H18: yes | I18: Requestor | K18: col E | M18: 1014: predecessor for: 1015, 1025 | O18: done | P18: complete | Q18: =VLOOKUP(B18,LOV!$B:$C,2,FALSE) -> 10 | R18: =VLOOKUP(B18,LOV!$B:$D,3,FALSE) -> AA | S18: =VLOOKUP($X18,LOV!$F:$L,2,FALSE) -> WK1 | T18: =VLOOKUP($X18,LOV!$F:$L,7,FALSE) -> 45916 | U18: 1 | V18: 2 | W18: =IF(ISNUMBER(V18),HLOOKUP(V18,$V$1:$AA$2,2,FALSE)*E18,"") -> 1 | X18: A | Y18: 45919 | Z18: 45922 | AA18: 45922
A19: 1015 | B19: Requestor - Project Initiation | C19: Product Setup | D19: Project Name or Number | E19: 1 | F19: 24 | G19: free form | H19: yes | I19: Requestor | K19: col G | M19: 1015: dependent on 1014 PROJECT TYPE: PDR and SCR is text (ex Tasty) PWR is numeric | O19: done | P19: complete | Q19: =VLOOKUP(B19,LOV!$B:$C,2,FALSE) -> 10 | R19: =VLOOKUP(B19,LOV!$B:$D,3,FALSE) -> AA | S19: =VLOOKUP($X19,LOV!$F:$L,2,FALSE) -> WK1 | T19: =VLOOKUP($X19,LOV!$F:$L,7,FALSE) -> 45916 | U19: 1 | V19: 1 | W19: =IF(ISNUMBER(V19),HLOOKUP(V19,$V$1:$AA$2,2,FALSE)*E19,"") -> 0.5 | X19: A | Y19: 45919 | Z19: 45922 | AA19: 45922
A20: 1016 | B20: Requestor - Project Initiation | C20: Product Setup | D20: Set Category | E20: 1 | F20: 0 | G20: dd: reference list: RDL_Categories.xlsx | H20: yes | I20: Requestor | K20: col I | L20: …not in Trng_deck.ppt; Bars, Crackers, Other Convenience, Salty Snacks, Frozen, Toaster Pastries, Veggies | M20: no known BR based on data entered | O20: done | P20: complete | Q20: =VLOOKUP(B20,LOV!$B:$C,2,FALSE) -> 10 | R20: =VLOOKUP(B20,LOV!$B:$D,3,FALSE) -> AA | S20: =VLOOKUP($X20,LOV!$F:$L,2,FALSE) -> WK1 | T20: =VLOOKUP($X20,LOV!$F:$L,7,FALSE) -> 45916 | U20: 1 | V20: 1 | W20: =IF(ISNUMBER(V20),HLOOKUP(V20,$V$1:$AA$2,2,FALSE)*E20,"") -> 0.5 | X20: A | Y20: 45919 | Z20: 45922 | AA20: 45922
A21: 1017 | B21: Requestor - Project Initiation | C21: Product Setup | D21: Brief Product Description | E21: 1 | F21: 24, 33, 73 | G21: free form | H21: yes | I21: Requestor | J21: LIM | K21: col K | L21: used for naming NIF form, but do not incorporate into AI | M21: no more than 40 characters | O21: done | P21: complete | Q21: =VLOOKUP(B21,LOV!$B:$C,2,FALSE) -> 10 | R21: =VLOOKUP(B21,LOV!$B:$D,3,FALSE) -> AA | S21: =VLOOKUP($X21,LOV!$F:$L,2,FALSE) -> WK1 | T21: =VLOOKUP($X21,LOV!$F:$L,7,FALSE) -> 45916 | U21: 1 | V21: 2 | W21: =IF(ISNUMBER(V21),HLOOKUP(V21,$V$1:$AA$2,2,FALSE)*E21,"") -> 1 | X21: B | Y21: 45919 | Z21: 45922 | AA21: 45922
A22: 1018 | B22: Requestor - Project Initiation | C22: Product Setup | D22: Brief Project Overview and Technical Notes | E22: 1 | F22: 24, 33, 73 | G22: free form | H22: yes | I22: Requestor | J22: LIM | K22: col M | L22: Be as detailed as possible and provide the flavor, package size and can size, if known | M22: no known BR based on data entered | O22: done | P22: complete | Q22: =VLOOKUP(B22,LOV!$B:$C,2,FALSE) -> 10 | R22: =VLOOKUP(B22,LOV!$B:$D,3,FALSE) -> AA | S22: =VLOOKUP($X22,LOV!$F:$L,2,FALSE) -> WK1 | T22: =VLOOKUP($X22,LOV!$F:$L,7,FALSE) -> 45916 | U22: 1 | V22: 2 | W22: =IF(ISNUMBER(V22),HLOOKUP(V22,$V$1:$AA$2,2,FALSE)*E22,"") -> 1 | X22: B | Y22: 45919 | Z22: 45922 | AA22: 45922
A23: 1019 | B23: Requestor - Project Initiation | C23: Stated Weights/Case Count | D23: Stated Weight Applicable For | E23: 1 | F23: 24, 33, 73 | G23: dd: PACKAGE, INNER ITEM/POUCH | H23: yes | I23: Requestor | J23: LIM | K23: col O | L23: informational only | M23: no known BR based on data entered | O23: done | P23: complete | Q23: =VLOOKUP(B23,LOV!$B:$C,2,FALSE) -> 10 | R23: =VLOOKUP(B23,LOV!$B:$D,3,FALSE) -> AA | S23: =VLOOKUP($X23,LOV!$F:$L,2,FALSE) -> WK1 | T23: =VLOOKUP($X23,LOV!$F:$L,7,FALSE) -> 45916 | U23: 2 | V23: 2 | W23: =IF(ISNUMBER(V23),HLOOKUP(V23,$V$1:$AA$2,2,FALSE)*E23,"") -> 1 | X23: B | Y23: 45919 | Z23: 45923 | AA23: 45929
A24: 1020 | B24: Requestor - Project Initiation | C24: Stated Weights/Case Count | D24: Stated Weight Status | E24: 1 | F24: 24, 33, 73 | G24: dd: ESTIMATED, FINALIZED | H24: yes | I24: Requestor | J24: LIM | K24: col Q | L24: informational only | M24: no known BR based on data entered | O24: done | P24: complete | Q24: =VLOOKUP(B24,LOV!$B:$C,2,FALSE) -> 10 | R24: =VLOOKUP(B24,LOV!$B:$D,3,FALSE) -> AA | S24: =VLOOKUP($X24,LOV!$F:$L,2,FALSE) -> WK1 | T24: =VLOOKUP($X24,LOV!$F:$L,7,FALSE) -> 45916 | U24: 2 | V24: 2 | W24: =IF(ISNUMBER(V24),HLOOKUP(V24,$V$1:$AA$2,2,FALSE)*E24,"") -> 1 | X24: B | Y24: 45919 | Z24: 45923 | AA24: 45929
A25: 1021 | B25: Requestor - Project Initiation | C25: Stated Weights/Case Count | D25: Stated Net Weight | E25: 1 | F25: 24, 33, 73, 99 | G25: free form | H25: yes | I25: Requestor | J25: LIM, Packaging Tech | K25: col S | L25: informational only | M25: no known BR based on data entered | O25: done | P25: complete | Q25: =VLOOKUP(B25,LOV!$B:$C,2,FALSE) -> 10 | R25: =VLOOKUP(B25,LOV!$B:$D,3,FALSE) -> AA | S25: =VLOOKUP($X25,LOV!$F:$L,2,FALSE) -> WK1 | T25: =VLOOKUP($X25,LOV!$F:$L,7,FALSE) -> 45916 | U25: 2 | V25: 1 | W25: =IF(ISNUMBER(V25),HLOOKUP(V25,$V$1:$AA$2,2,FALSE)*E25,"") -> 0.5 | X25: B | Y25: 45919 | Z25: 45923 | AA25: 45929
A26: 1022 | B26: Requestor - Project Initiation | C26: Stated Weights/Case Count | D26: Stated Net Weight UOM | E26: 1 | F26: 24, 33, 73 | G26: dd: OZ, LB, G, KG | H26: yes | I26: Requestor | J26: LIM | K26: col U | L26: informational only | M26: no known BR based on data entered | O26: done | P26: complete | Q26: =VLOOKUP(B26,LOV!$B:$C,2,FALSE) -> 10 | R26: =VLOOKUP(B26,LOV!$B:$D,3,FALSE) -> AA | S26: =VLOOKUP($X26,LOV!$F:$L,2,FALSE) -> WK1 | T26: =VLOOKUP($X26,LOV!$F:$L,7,FALSE) -> 45916 | U26: 2 | V26: 1 | W26: =IF(ISNUMBER(V26),HLOOKUP(V26,$V$1:$AA$2,2,FALSE)*E26,"") -> 0.5 | X26: B | Y26: 45919 | Z26: 45923 | AA26: 45929
A27: 1023 | B27: Requestor - Project Initiation | C27: Stated Weights/Case Count | D27: Case Count Status | E27: 1 | F27: 24, 33, 73 | G27: dd: ESTIMATED, FINALIZED | H27: yes | I27: Requestor | J27: LIM | K27: col W | L27: informational only | M27: no known BR based on data entered | O27: done | P27: complete | Q27: =VLOOKUP(B27,LOV!$B:$C,2,FALSE) -> 10 | R27: =VLOOKUP(B27,LOV!$B:$D,3,FALSE) -> AA | S27: =VLOOKUP($X27,LOV!$F:$L,2,FALSE) -> WK1 | T27: =VLOOKUP($X27,LOV!$F:$L,7,FALSE) -> 45916 | U27: 2 | V27: 2 | W27: =IF(ISNUMBER(V27),HLOOKUP(V27,$V$1:$AA$2,2,FALSE)*E27,"") -> 1 | X27: B | Y27: 45919 | Z27: 45923 | AA27: 45929
A28: 1024 | B28: Requestor - Project Initiation | C28: Stated Weights/Case Count | D28: Case Count | E28: 1 | F28: 24, 33, 73 | G28: free form | H28: yes | I28: Requestor | J28: LIM | K28: col Y | L28: informational only | M28: no known BR based on data entered | O28: done | P28: complete | Q28: =VLOOKUP(B28,LOV!$B:$C,2,FALSE) -> 10 | R28: =VLOOKUP(B28,LOV!$B:$D,3,FALSE) -> AA | S28: =VLOOKUP($X28,LOV!$F:$L,2,FALSE) -> WK1 | T28: =VLOOKUP($X28,LOV!$F:$L,7,FALSE) -> 45916 | U28: 2 | V28: 3 | W28: =IF(ISNUMBER(V28),HLOOKUP(V28,$V$1:$AA$2,2,FALSE)*E28,"") -> 1.5 | X28: B | Y28: 45919 | Z28: 45923 | AA28: 45929
A29: 1025 | B29: Requestor - Project Initiation | C29: Reference Material | D29: Like SKU / Reference Material Number | E29: 1 | F29: 25 | G29: SAP db list | H29: conditional | I29: Requestor | K29: NOT in BR.xlsx | L29: functionality of the SAP db is not needed in AI tool | M29: 1025: dependent on 1014 PROJECT TYPE: KUBIC (required) | O29: done | P29: complete | Q29: =VLOOKUP(B29,LOV!$B:$C,2,FALSE) -> 10 | R29: =VLOOKUP(B29,LOV!$B:$D,3,FALSE) -> AA | S29: =VLOOKUP($X29,LOV!$F:$L,2,FALSE) -> WK1 | T29: =VLOOKUP($X29,LOV!$F:$L,7,FALSE) -> 45916 | U29: 3 | V29: 3 | W29: =IF(ISNUMBER(V29),HLOOKUP(V29,$V$1:$AA$2,2,FALSE)*E29,"") -> 1.5 | X29: B | Y29: 45919 | Z29: 45923 | AA29: 45929
A30: 1026 | B30: Requestor - Project Initiation | C30: Product Determination Questions | D30: Approved to sell via Ecommerce | E30: 1 | F30: 25, 26 | G30: dd: YES, NO | H30: yes | I30: Requestor | K30: col Z | L30: CASE and DISPLAY only; If YES, then loads record: TRADE CHANNEL (1166)=ONLINE | M30: 1026 dependent PRODUCT TYPE (1009)=ECOMM or DTC BUNDLE, then this is defaulted to YES (locks field); If Product Country (1008) CANADA then default to NO; Form Type (1007) DISPLAY=open but not required, CASE=required, WIP=not available | O30: done | P30: complete | Q30: =VLOOKUP(B30,LOV!$B:$C,2,FALSE) -> 10 | R30: =VLOOKUP(B30,LOV!$B:$D,3,FALSE) -> AA | S30: =VLOOKUP($X30,LOV!$F:$L,2,FALSE) -> WK1 | T30: =VLOOKUP($X30,LOV!$F:$L,7,FALSE) -> 45916 | U30: 3 | V30: 1 | W30: =IF(ISNUMBER(V30),HLOOKUP(V30,$V$1:$AA$2,2,FALSE)*E30,"") -> 0.5 | X30: B | Y30: 45919 | Z30: 45924 | AA30: 45929
A31: 1027 | B31: Requestor - Project Initiation | C31: Product Determination Questions | D31: Is product designated to one customer | E31: 1 | F31: 25, 26 | G31: dd: YES, NO | H31: yes | I31: Requestor | K31: col AB | L31: CASE and DISPLAY | M31: 1027: predecessor to 1028, 1029 | O31: done | P31: complete | Q31: =VLOOKUP(B31,LOV!$B:$C,2,FALSE) -> 10 | R31: =VLOOKUP(B31,LOV!$B:$D,3,FALSE) -> AA | S31: =VLOOKUP($X31,LOV!$F:$L,2,FALSE) -> WK1 | T31: =VLOOKUP($X31,LOV!$F:$L,7,FALSE) -> 45916 | U31: 3 | V31: 1 | W31: =IF(ISNUMBER(V31),HLOOKUP(V31,$V$1:$AA$2,2,FALSE)*E31,"") -> 0.5 | X31: B | Y31: 45919 | Z31: 45923 | AA31: 45929
A32: 1028 | B32: Requestor - Project Initiation | C32: Product Determination Questions | D32: Designated Customer Name | E32: 1 | F32: 25, 26 | G32: dd: reference list: PRL: Designated Customer Name | H32: conditional | I32: Requestor | K32: col AD | L32: CASE and DISPLAY | M32: 1028 dependent on: Is product designated to one customer (1027) =YES | O32: done | P32: complete | Q32: =VLOOKUP(B32,LOV!$B:$C,2,FALSE) -> 10 | R32: =VLOOKUP(B32,LOV!$B:$D,3,FALSE) -> AA | S32: =VLOOKUP($X32,LOV!$F:$L,2,FALSE) -> WK1 | T32: =VLOOKUP($X32,LOV!$F:$L,7,FALSE) -> 45916 | U32: 3 | V32: 2 | W32: =IF(ISNUMBER(V32),HLOOKUP(V32,$V$1:$AA$2,2,FALSE)*E32,"") -> 1 | X32: B | Y32: 45919 | Z32: 45923 | AA32: 45929
A33: 1029 | B33: Requestor - Project Initiation | C33: Product Determination Questions | D33: Include Designated Cust In Material Desc | E33: 1 | F33: 25, 26 | G33: dd: YES, NO | H33: yes | I33: Requestor | K33: col AF | L33: CASE and DISPLAY | M33: 1029 dependent on: Is product designated to one customer (1027)=YES; 1029 predecessor to 1129 | O33: done | P33: complete | Q33: =VLOOKUP(B33,LOV!$B:$C,2,FALSE) -> 10 | R33: =VLOOKUP(B33,LOV!$B:$D,3,FALSE) -> AA | S33: =VLOOKUP($X33,LOV!$F:$L,2,FALSE) -> WK1 | T33: =VLOOKUP($X33,LOV!$F:$L,7,FALSE) -> 45916 | U33: 3 | V33: 1 | W33: =IF(ISNUMBER(V33),HLOOKUP(V33,$V$1:$AA$2,2,FALSE)*E33,"") -> 0.5 | X33: B | Y33: 45919 | Z33: 45923 | AA33: 45929
A34: 1030 | B34: Requestor - Project Initiation | C34: Product Determination Questions | D34: Variety Pack | E34: 1 | F34: 25 | G34: dd: YES, NO | H34: yes | I34: Requestor | K34: col AH | L34: CASE | M34: 1030 dependent on Product Type (1009) and Product Subtype (1010); Flowchart: Variety Pack | O34: done | P34: complete | Q34: =VLOOKUP(B34,LOV!$B:$C,2,FALSE) -> 10 | R34: =VLOOKUP(B34,LOV!$B:$D,3,FALSE) -> AA | S34: =VLOOKUP($X34,LOV!$F:$L,2,FALSE) -> WK1 | T34: =VLOOKUP($X34,LOV!$F:$L,7,FALSE) -> 45916 | U34: 3 | V34: 1 | W34: =IF(ISNUMBER(V34),HLOOKUP(V34,$V$1:$AA$2,2,FALSE)*E34,"") -> 0.5 | X34: B | Y34: 45922 | Z34: 45923 | AA34: 45929
A35: 1031 | B35: Requestor - Project Initiation | C35: Product Determination Questions | D35: Variety Pack components have UPC codes | E35: 1 | F35: 25 | G35: dd: YES, NO | H35: yes | I35: Requestor | K35: col AJ | L35: CASE | M35: 1031 predecessor to 1188-1192; Flowchart: Variety Pack | O35: done | P35: complete | Q35: =VLOOKUP(B35,LOV!$B:$C,2,FALSE) -> 10 | R35: =VLOOKUP(B35,LOV!$B:$D,3,FALSE) -> AA | S35: =VLOOKUP($X35,LOV!$F:$L,2,FALSE) -> WK1 | T35: =VLOOKUP($X35,LOV!$F:$L,7,FALSE) -> 45916 | U35: 3 | V35: 1 | W35: =IF(ISNUMBER(V35),HLOOKUP(V35,$V$1:$AA$2,2,FALSE)*E35,"") -> 0.5 | X35: B | Y35: 45922 | Z35: 45923 | AA35: 45929
A36: 1032 | B36: Requestor - Project Initiation | C36: Product Determination Questions | D36: Build SKU Using Existing Package UPCs | E36: 1 | F36: 25, 26, 27 | G36: dd: YES, NO | H36: yes | I36: Requestor | K36: col AL | L36: autofill by FORM TYPE: CASE=YES, DISPLAY=NO, and WIP=NO | M36: Flowchart: Build SKU / Existing Printed | O36: done | P36: complete | Q36: =VLOOKUP(B36,LOV!$B:$C,2,FALSE) -> 10 | R36: =VLOOKUP(B36,LOV!$B:$D,3,FALSE) -> AA | S36: =VLOOKUP($X36,LOV!$F:$L,2,FALSE) -> WK2 | T36: =VLOOKUP($X36,LOV!$F:$L,7,FALSE) -> 45922 | U36: 3 | V36: 1 | W36: =IF(ISNUMBER(V36),HLOOKUP(V36,$V$1:$AA$2,2,FALSE)*E36,"") -> 0.5 | X36: C | Y36: 45922 | Z36: 45924 | AA36: 45929
A37: 1033 | B37: Requestor - Project Initiation | C37: Product Determination Questions | D37: Is this item owned by Away From Home | E37: 1 | F37: 25, 26, 27 | G37: dd: YES, NO | H37: yes | I37: Requestor | K37: col AN | L37: CASE, DISPLAY and WIP | M37: 1033 predecessor to: external material group (1085) | O37: done | P37: complete | Q37: =VLOOKUP(B37,LOV!$B:$C,2,FALSE) -> 10 | R37: =VLOOKUP(B37,LOV!$B:$D,3,FALSE) -> AA | S37: =VLOOKUP($X37,LOV!$F:$L,2,FALSE) -> WK2 | T37: =VLOOKUP($X37,LOV!$F:$L,7,FALSE) -> 45922 | U37: 3 | V37: 1 | W37: =IF(ISNUMBER(V37),HLOOKUP(V37,$V$1:$AA$2,2,FALSE)*E37,"") -> 0.5 | X37: C | Y37: 45922 | Z37: 45925 | AA37: 45929
A38: 1034 | B38: Requestor - Project Initiation | C38: Product Determination Questions | D38: Is this an Export Product | E38: 1 | F38: 26, 27, 28 | G38: dd: YES, NO | H38: yes | I38: Requestor | K38: col AP | L38: CASE, DISPLAY and WIP | M38: 1034 predecessor to: external material group (1085), build sku..export (1035), list existing export (1036) | O38: done | P38: complete | Q38: =VLOOKUP(B38,LOV!$B:$C,2,FALSE) -> 10 | R38: =VLOOKUP(B38,LOV!$B:$D,3,FALSE) -> AA | S38: =VLOOKUP($X38,LOV!$F:$L,2,FALSE) -> WK2 | T38: =VLOOKUP($X38,LOV!$F:$L,7,FALSE) -> 45922 | U38: 3 | V38: 1 | W38: =IF(ISNUMBER(V38),HLOOKUP(V38,$V$1:$AA$2,2,FALSE)*E38,"") -> 0.5 | X38: C | Y38: 45922 | Z38: 45925 | AA38: 45929
A39: 1035 | B39: Requestor - Project Initiation | C39: Product Determination Questions | D39: Build SKU Using Existing Export UPCs | E39: 1 | F39: 27, 28 | G39: dd: YES, NO | H39: yes | I39: Requestor | K39: col AR | L39: CASE and WIP | M39: 1035 dependent on 1034 | O39: done | P39: complete | Q39: =VLOOKUP(B39,LOV!$B:$C,2,FALSE) -> 10 | R39: =VLOOKUP(B39,LOV!$B:$D,3,FALSE) -> AA | S39: =VLOOKUP($X39,LOV!$F:$L,2,FALSE) -> WK2 | T39: =VLOOKUP($X39,LOV!$F:$L,7,FALSE) -> 45922 | U39: 3 | V39: 1 | W39: =IF(ISNUMBER(V39),HLOOKUP(V39,$V$1:$AA$2,2,FALSE)*E39,"") -> 0.5 | X39: C | Y39: 45922 | Z39: 45925 | AA39: 45929
A40: 1036 | B40: Requestor - Project Initiation | C40: Product Determination Questions | D40: List Existing Export UPC Codes | E40: 1 | F40: 27, 28 | G40: free form | H40: conditional | I40: Requestor | K40: col AT | L40: CASE and WIP | M40: 1036 dependent on 1034 | O40: done | P40: complete | Q40: =VLOOKUP(B40,LOV!$B:$C,2,FALSE) -> 10 | R40: =VLOOKUP(B40,LOV!$B:$D,3,FALSE) -> AA | S40: =VLOOKUP($X40,LOV!$F:$L,2,FALSE) -> WK2 | T40: =VLOOKUP($X40,LOV!$F:$L,7,FALSE) -> 45922 | U40: 3 | V40: 2 | W40: =IF(ISNUMBER(V40),HLOOKUP(V40,$V$1:$AA$2,2,FALSE)*E40,"") -> 1 | X40: C | Y40: 45922 | Z40: 45925 | AA40: 45929
...

Sheet Sprint fields
A1: Training Section - fields & complexity | P1: Complexity by Week and Training Section Priority | AC1: Timing Status by Week by Training Section Priority | AS1: Training Sections - number of fields to be defined
U5: Complexity
A6: # fields | H6: COMPLEXITY (3..1,0) 3-high 2-med 1-low 0-autofill | P6: Count of field names in Trng deck | U6: Complexity | AL6: Values | AS6: # fields
A7: Week | B7: Week Beginning Date | C7: Sprint | D7: Trng Sectn Priority | E7: Trng Sectn # | F7: Training Section | G7: field names in Trng deck | H7: 3 | I7: 2 | J7: 1 | K7: 0 | L7: Grand Total | P7: Week | Q7: Week Beginning Date | R7: Trng Sectn Priority | S7: Trng Sectn # | T7: Training Section | U7: 3 | V7: 2 | W7: 1 | X7: 0 | Y7: Grand Total | AC7: Week | AD7: Week Beginning Date | AE7: Sprint | AF7: Trng Sectn # | AG7: Training Section | AH7: UNIQUE FIELD # (order in Trng deck) | AI7: field names in Trng deck | AJ7: Business Rule status | AK7: COMPLEXITY (3..1,0) 3-high 2-med 1-low 0-autofill | AL7: # fields | AM7: Business Reviewd | AN7: Formatted Business Rules | AO7: Given to AI team | AS7: Trng Sectn # | AT7: Training Section | AU7: Total
A8: WK1 | B8: 45916 | C8: A | D8: AA | E8: 10 | F8: Requestor - Project Initiation | G8: Form Type | H8: 1 | L8: 1 | P8: WK1 | Q8: 45916 | R8: AA | S8: 10 | T8: Requestor - Project Initiation | U8: 6 | V8: 7 | W8: 12 | Y8: 25 | AC8: WK1 | AD8: 45916 | AE8: A | AF8: 10 | AG8: Requestor - Project Initiation | AH8: 1007 | AI8: Form Type | AJ8: done | AK8: 3 | AL8: 1 | AM8: 1 | AN8: 1 | AO8: 1 | AS8: 10 | AT8: Requestor - Project Initiation | AU8: 55
G9: Product Country | H9: 1 | L9: 1 | P9: WK1 Total | U9: 6 | V9: 7 | W9: 12 | Y9: 25 | AH9: 1008 | AI9: Product Country | AJ9: done | AK9: 3 | AL9: 1 | AM9: 1 | AN9: 1 | AO9: 1 | AS9: 20 | AT9: LIM - Initial Review | AU9: 15
G10: Product Sub Type | H10: 1 | L10: 1 | P10: WK2 | Q10: 45922 | R10: AA | S10: 10 | T10: Requestor - Project Initiation | U10: 1 | V10: 13 | W10: 10 | X10: 6 | Y10: 30 | AH10: 1009 | AI10: Product Type | AJ10: done | AK10: 3 | AL10: 1 | AM10: 1 | AN10: 1 | AO10: 1 | AS10: 30 | AT10: LIM - LIM REPORT | AU10: 1
G11: Product Type | H11: 1 | L11: 1 | R11: BB | S11: 50 | T11: LIM - Forecast Approval | U11: 3 | V11: 9 | W11: 17 | X11: 23 | Y11: 52 | AH11: 1010 | AI11: Product Sub Type | AJ11: done | AK11: 3 | AL11: 1 | AM11: 1 | AN11: 1 | AO11: 1 | AS11: 40 | AT11: Masterfiles - Get Codes | AU11: 13
G12: Project Name or Number | J12: 1 | L12: 1 | R12: CC | S12: 100 | T12: Requestor Update | V12: 2 | W12: 17 | X12: 5 | Y12: 24 | AH12: 1011 | AI12: Is this a Pringles product | AJ12: done | AK12: 1 | AL12: 1 | AM12: 1 | AN12: 1 | AO12: 1 | AS12: 50 | AT12: LIM - Forecast Approval | AU12: 52
G13: Project Type | I13: 1 | L13: 1 | P13: WK2 Total | U13: 4 | V13: 24 | W13: 44 | X13: 34 | Y13: 106 | AH13: 1012 | AI13: Is this an RX Product | AJ13: done | AK13: 1 | AL13: 1 | AM13: 1 | AN13: 1 | AO13: 1 | AS13: 60 | AT13: Masterfiles - Get Codes Forecast | AU13: 2
G14: Set Category | J14: 1 | L14: 1 | P14: WK3 | Q14: 45929 | R14: CC | S14: 100 | T14: Requestor Update | V14: 2 | W14: 21 | X14: 8 | Y14: 31 | AH14: 1014 | AI14: Project Type | AJ14: done | AK14: 2 | AL14: 1 | AM14: 1 | AN14: 1 | AO14: 1 | AS14: 70 | AT14: LIM - Launch | AU14: 1
G15: Is this a Pringles product | J15: 1 | L15: 1 | S15: 230 | T15: Requestor - Req Launch DTC | U15: 5 | V15: 1 | W15: 3 | Y15: 9 | AH15: 1015 | AI15: Project Name or Number | AJ15: done | AK15: 1 | AL15: 1 | AM15: 1 | AN15: 1 | AO15: 1 | AS15: 80 | AT15: LIM Launch - Update | AU15: 1
G16: Is this an RX Product | J16: 1 | L16: 1 | R16: DD | S16: 20 | T16: LIM - Initial Review | V16: 1 | W16: 14 | Y16: 15 | AH16: 1016 | AI16: Set Category | AJ16: done | AK16: 1 | AL16: 1 | AM16: 1 | AN16: 1 | AO16: 1 | AS16: 90 | AT16: ZNIF Dashboard - view only | AU16: 1
C17: B | D17: AA | E17: 10 | F17: Requestor - Project Initiation | G17: Approved to sell via Ecommerce | J17: 1 | L17: 1 | S17: 70 | T17: LIM - Launch | V17: 1 | Y17: 1 | AE17: B | AF17: 10 | AG17: Requestor - Project Initiation | AH17: 1013 | AI17: SAP Material Number | AJ17: done | AK17: 1 | AL17: 1 | AM17: 1 | AN17: 1 | AO17: 1 | AS17: 100 | AT17: Requestor Update | AU17: 55
G18: Brief Product Description | I18: 1 | L18: 1 | S18: 80 | T18: LIM Launch - Update | W18: 1 | Y18: 1 | AH18: 1017 | AI18: Brief Product Description | AJ18: done | AK18: 2 | AL18: 1 | AM18: 1 | AN18: 1 | AO18: 1 | AS18: 110 | AT18: LIM - Update | AU18: 11
G19: Brief Project Overview and Technical Notes | I19: 1 | L19: 1 | S19: 110 | T19: LIM - Update | V19: 1 | W19: 6 | X19: 4 | Y19: 11 | AH19: 1018 | AI19: Brief Project Overview and Technical Notes | AJ19: done | AK19: 2 | AL19: 1 | AM19: 1 | AN19: 1 | AO19: 1 | AS19: 120 | AT19: EPM Finance - Update | AU19: 2
G20: Case Count | H20: 1 | L20: 1 | S20: 200 | T20: LIM - Approval/NIF Dashboard | W20: 2 | Y20: 2 | AH20: 1019 | AI20: Stated Weight Applicable For | AJ20: done | AK20: 2 | AL20: 1 | AM20: 1 | AN20: 1 | AO20: 1 | AS20: 130 | AT20: Data Integrity (DI) - Review | AU20: 1
G21: Case Count Status | I21: 1 | L21: 1 | P21: WK3 Total | U21: 5 | V21: 6 | W21: 47 | X21: 12 | Y21: 70 | AH21: 1020 | AI21: Stated Weight Status | AJ21: done | AK21: 2 | AL21: 1 | AM21: 1 | AN21: 1 | AO21: 1 | AS21: 140 | AT21: R&D Quality - Update | AU21: 4
G22: Designated Customer Name | I22: 1 | L22: 1 | P22: WK4 | Q22: 45936 | R22: EE | S22: 150 | T22: Nutrition Labeling - Update | U22: 4 | W22: 20 | Y22: 24 | AH22: 1021 | AI22: Stated Net Weight | AJ22: done | AK22: 1 | AL22: 1 | AM22: 1 | AN22: 1 | AO22: 1 | AS22: 150 | AT22: Nutrition Labeling - Update | AU22: 24
G23: Like SKU / Reference Material Number | H23: 1 | L23: 1 | S23: 160 | T23: Packaging Tech - Update | W23: 15 | X23: 4 | Y23: 19 | AH23: 1022 | AI23: Stated Net Weight UOM | AJ23: done | AK23: 1 | AL23: 1 | AM23: 1 | AN23: 1 | AO23: 1 | AS23: 160 | AT23: Packaging Tech - Update | AU23: 19
G24: SAP Material Number | J24: 1 | L24: 1 | P24: WK4 Total | U24: 4 | W24: 35 | X24: 4 | Y24: 43 | AH24: 1023 | AI24: Case Count Status | AJ24: done | AK24: 2 | AL24: 1 | AM24: 1 | AN24: 1 | AO24: 1 | AS24: 170 | AT24: CA Finance Tax | AU24: 2
G25: Stated Net Weight | J25: 1 | L25: 1 | P25: WK5 | Q25: 45943 | R25: FF | S25: 120 | T25: EPM Finance - Update | W25: 2 | Y25: 2 | AH25: 1024 | AI25: Case Count | AJ25: done | AK25: 3 | AL25: 1 | AM25: 1 | AN25: 1 | AO25: 1 | AS25: 180 | AT25: Category Finance - update | AU25: 1
G26: Stated Net Weight UOM | J26: 1 | L26: 1 | S26: 130 | T26: Data Integrity (DI) - Review | W26: 1 | Y26: 1 | AH26: 1025 | AI26: Like SKU / Reference Material Number | AJ26: done | AK26: 3 | AL26: 1 | AM26: 1 | AN26: 1 | AO26: 1 | AS26: 190 | AT26: Data Integrity (DI) - Hierarchy | AU26: 1
G27: Stated Weight Applicable For | I27: 1 | L27: 1 | S27: 140 | T27: R&D Quality - Update | W27: 4 | Y27: 4 | AH27: 1026 | AI27: Approved to sell via Ecommerce | AJ27: done | AK27: 1 | AL27: 1 | AM27: 1 | AN27: 1 | AO27: 1 | AS27: 200 | AT27: LIM - Approval/NIF Dashboard | AU27: 2
G28: Stated Weight Status | I28: 1 | L28: 1 | S28: 170 | T28: CA Finance Tax | W28: 2 | Y28: 2 | AH28: 1027 | AI28: Is product designated to one customer | AJ28: done | AK28: 1 | AL28: 1 | AM28: 1 | AN28: 1 | AO28: 1 | AS28: 210 | AT28: Masterfiles - Approval | AU28: 18
G29: Is product designated to one customer | J29: 1 | L29: 1 | S29: 180 | T29: Category Finance - update | W29: 1 | Y29: 1 | AH29: 1028 | AI29: Designated Customer Name | AJ29: done | AK29: 2 | AL29: 1 | AM29: 1 | AN29: 1 | AO29: 1 | AS29: 220 | AT29: Masterfiles - Create Plant Extensions, pricing & BOM's | AU29: 17
G30: Include Designated Cust In Material Desc | J30: 1 | L30: 1 | S30: 190 | T30: Data Integrity (DI) - Hierarchy | W30: 1 | Y30: 1 | AH30: 1029 | AI30: Include Designated Cust In Material Desc | AJ30: done | AK30: 1 | AL30: 1 | AM30: 1 | AN30: 1 | AO30: 1 | AS30: 230 | AT30: Requestor - Req Launch DTC | AU30: 9
G31: Variety Pack | J31: 1 | L31: 1 | R31: GG | S31: 40 | T31: Masterfiles - Get Codes | W31: 6 | X31: 7 | Y31: 13 | AH31: 1030 | AI31: Variety Pack | AJ31: done | AK31: 1 | AL31: 1 | AM31: 1 | AN31: 1 | AO31: 1 | AS31: Grand Total | AU31: 307
G32: Variety Pack components have UPC codes | J32: 1 | L32: 1 | S32: 60 | T32: Masterfiles - Get Codes Forecast | W32: 2 | Y32: 2 | AH32: 1031 | AI32: Variety Pack components have UPC codes | AJ32: done | AK32: 1 | AL32: 1 | AM32: 1 | AN32: 1 | AO32: 1
A33: WK1 Total | H33: 6 | I33: 7 | J33: 12 | L33: 25 | R33: HH | S33: 210 | T33: Masterfiles - Approval | W33: 15 | X33: 3 | Y33: 18 | AC33: WK1 Total | AL33: 25 | AM33: 25 | AN33: 25 | AO33: 25
A34: WK2 | B34: 45922 | C34: C | D34: AA | E34: 10 | F34: Requestor - Project Initiation | G34: List Existing Export UPC Codes | I34: 1 | L34: 1 | S34: 220 | T34: Masterfiles - Create Plant Extensions, pricing & BOM's | W34: 15 | X34: 2 | Y34: 17 | AC34: WK2 | AD34: 45922 | AE34: C | AF34: 10 | AG34: Requestor - Project Initiation | AH34: 1032 | AI34: Build SKU Using Existing Package UPCs | AJ34: done | AK34: 1 | AL34: 1 | AM34: 1 | AN34: 1 | AO34: 1
G35: List Existing Private UPCs | I35: 1 | L35: 1 | R35: II | S35: 30 | T35: LIM - LIM REPORT | W35: 1 | Y35: 1 | AH35: 1033 | AI35: Is this item owned by Away From Home | AJ35: done | AK35: 1 | AL35: 1 | AM35: 1 | AN35: 1 | AO35: 1
G36: Private Label Name | I36: 1 | L36: 1 | S36: 90 | T36: ZNIF Dashboard - view only | X36: 1 | Y36: 1 | AH36: 1034 | AI36: Is this an Export Product | AJ36: done | AK36: 1 | AL36: 1 | AM36: 1 | AN36: 1 | AO36: 1
G37: Build SKU Using Existing Package UPCs | J37: 1 | L37: 1 | P37: WK5 Total | W37: 50 | X37: 13 | Y37: 63 | AH37: 1035 | AI37: Build SKU Using Existing Export UPCs | AJ37: done | AK37: 1 | AL37: 1 | AM37: 1 | AN37: 1 | AO37: 1
G38: Is this item owned by Away From Home | J38: 1 | L38: 1 | P38: Grand Total | U38: 19 | V38: 37 | W38: 188 | X38: 63 | Y38: 307 | AH38: 1036 | AI38: List Existing Export UPC Codes | AJ38: done | AK38: 2 | AL38: 1 | AM38: 1 | AN38: 1 | AO38: 1
G39: Is this an Export Product | J39: 1 | L39: 1 | AH39: 1037 | AI39: Private Label | AJ39: done | AK39: 1 | AL39: 1 | AM39: 1 | AN39: 1 | AO39: 1
G40: Build SKU Using Existing Export UPCs | J40: 1 | L40: 1 | AH40: 1038 | AI40: Private Label Name | AJ40: done | AK40: 2 | AL40: 1 | AM40: 1 | AN40: 1 | AO40: 1
G41: Private Label | J41: 1 | L41: 1 | AH41: 1039 | AI41: Build SKU Using Existing Private UPCs | AJ41: done | AK41: 1 | AL41: 1 | AM41: 1 | AN41: 1 | AO41: 1
G42: Build SKU Using Existing Private UPCs | J42: 1 | L42: 1 | AH42: 1040 | AI42: List Existing Private UPCs | AJ42: done | AK42: 2 | AL42: 1 | AM42: 1 | AN42: 1 | AO42: 1
G43: Data Sync(GDSN) | J43: 1 | L43: 1 | AH43: 1041 | AI43: Data Sync(GDSN) | AJ43: done | AK43: 1 | AL43: 1 | AM43: 1 | AN43: 1 | AO43: 1
...

Sheet Complexity
A1: Complexity: ALL - Most complex sections at top, with number of fields represented in the grid per user role | R1: Complexity: 3 and 2 - AI guidance necessary: 49 unique fields | AA1: Complexity: 1 - AI guidance possibly: 186 unique fields | AJ1: Complexity: 0 - definitions only: 63 unique fields
A6: Count of field names in Trng deck | C6: owner | R6: Count of field names in Trng deck | AA6: Count of field names in Trng deck | AJ6: Count of field names in Trng deck
A7: COMPLEXITY (3..1,0) 3-high 2-med 1-low 0-autofill | B7: Training Section | C7: CA Finance Tax | D7: Category Finance | E7: Data Integrity | F7: EPM Finance | G7: LIM | H7: Masterfiles | I7: Nutrition Labeling | J7: Packaging Tech | K7: R&D Quality | L7: Requestor | M7: Grand Total | R7: COMPLEXITY (3..1,0) 3-high 2-med 1-low 0-autofill | S7: field names in Trng deck | T7: owner | U7: types of fields | V7: section name | W7: Total | AA7: COMPLEXITY (3..1,0) 3-high 2-med 1-low 0-autofill | AB7: field names in Trng deck | AC7: owner | AD7: types of fields | AE7: section name | AF7: Total | AJ7: COMPLEXITY (3..1,0) 3-high 2-med 1-low 0-autofill | AK7: field names in Trng deck | AL7: owner | AM7: types of fields | AN7: section name | AO7: Total
A8: 3 | B8: LIM - Forecast Approval | G8: 3 | M8: 3 | R8: 3 | S8: 1. Validate Retail material Number (button) | T8: Requestor | U8: script button | V8: DTC Product Details | W8: 1 | AA8: 1 | AB8: 1st Arrival Date | AC8: Requestor | AD8: date | AE8: Product Details | AF8: 1 | AJ8: 0 | AK8: <=> | AL8: LIM | AM8: autofill | AN8: Alternate Units of Measure | AO8: 1
B9: Nutrition Labeling - Update | I9: 4 | M9: 4 | S9: 2. Import Alt UOM Table (button) | T9: Requestor | U9: script button | V9: DTC Product Details | W9: 1 | AB9: 1st Ship Date | AC9: Requestor | AD9: date | AE9: Product Details | AF9: 1 | AK9: 1st Arrival Date (Day) | AL9: Requestor | AM9: autofill | AN9: Product Details | AO9: 1
B10: Requestor - Project Initiation | L10: 7 | M10: 7 | S10: Brand Description | T10: LIM | U10: dd: reference list: PRL: Product Hierarchy Brand | V10: Product Hierarchy-Brand | W10: 1 | AB10: Approved to sell via Ecommerce | AC10: Requestor | AD10: dd: YES, NO | AE10: Product Determination Questions | AF10: 1 | AK10: 1st Ship Date (Day) | AL10: Requestor | AM10: autofill | AN10: Product Details | AO10: 1
B11: Requestor - Req Launch DTC | L11: 5 | M11: 5 | S11: Case Count | T11: Requestor | U11: free form | V11: Stated Weights/Case Count | W11: 1 | AB11: Assign Plant | AC11: Masterfiles | AD11: checkbox | AE11: VAS BOM Plant Assingments (CS07) | AF11: 1 | AK11: Alt UOM | AL11: Masterfiles | AM11: autofill | AN11: UPC, K#, and GTIN Codes | AO11: 1
A12: 3 Total | G12: 3 | I12: 4 | L12: 12 | M12: 19 | S12: DTC Form Launched (button) | T12: Requestor | U12: script button | V12: DTC Launch Validation | W12: 1 | AB12: Base Material | AC12: Requestor | AD12: free form | AE12: BOM Setup (VAS) | AF12: 1 | AK12: Alternate Category | AL12: Requestor | AM12: autofill | AN12: Alternate Hierarchy | AO12: 1
A13: 2 | B13: LIM - Forecast Approval | G13: 9 | M13: 9 | S13: Form Type | T13: Requestor | U13: dd: CASE, DISPLAY, WIP | V13: Product Setup | W13: 1 | AB13: Business Unit | AC13: Requestor | AD13: dd: reference list: PRL: Business Unit | AE13: Product Details | AF13: 1 | AK13: Alternate Market Segment | AL13: Requestor | AM13: autofill | AN13: Alternate Hierarchy | AO13: 1
B14: LIM - Initial Review | G14: 1 | M14: 1 | S14: Launch Later (No Save) (button) | T14: Requestor | U14: script button | V14: DTC Launch Validation | W14: 1 | AB14: Calculation Check | AC14: Requestor | AD14: free form | AE14: Variety Pack 0200 BOM Setup | AF14: 1 | AK14: Alternate Sub-Category | AL14: Requestor | AM14: autofill | AN14: Alternate Hierarchy | AO14: 1
B15: LIM - Launch | G15: 1 | M15: 1 | S15: Like SKU / Reference Material Number | T15: Requestor | U15: SAP db list | V15: Reference Material | W15: 1 | AB15: Case | AC15: Nutrition Labeling | AD15: free form | AE15: Net Wt. Statement for Graphics | AF15: 1 | AK15: Base UOM | AL15: LIM | AM15: autofill | AN15: Alternate Units of Measure | AO15: 1
B16: LIM - Update | G16: 1 | M16: 1 | S16: Metric Stated Net Package Weight (g) | T16: Nutrition Labeling | U16: calculation | V16: Food Weights in grams/ounces | W16: 1 | AB16: Category Finance | AC16: LIM | AD16: dd: user roles | AE16: Person Responsible | AF16: 1 | AK16: Brand Number | AL16: LIM | AM16: dd: reference list: PRL: Product Hierarchy Brand | AN16: Product Hierarchy-Brand | AO16: 1
B17: Requestor - Project Initiation | L17: 20 | M17: 20 | S17: Metric Stated Net Pouch Weight (g) | T17: Nutrition Labeling | U17: calculation | V17: Food Weights in grams/ounces | W17: 1 | AB17: Chocolate Enrobed | AC17: LIM | AD17: dd: YES, NO | AE17: General Product Data | AF17: 1 | AK17: Business Unit for Promo | AL17: Requestor | AM17: dd: reference list: PRL: Business Unit for Promo | AN17: Promotion | AO17: 1
B18: Requestor - Req Launch DTC | L18: 1 | M18: 1 | S18: Product Country | T18: Requestor | U18: dd: reference list: PRODUCT_COUNTRY.XLSX | V18: Product Setup | W18: 1 | AB18: Clamp Pressure | AC18: Packaging Tech | AD18: dd: reference list: PRL: Clamp Pressure | AE18: Packaging Details | AF18: 1 | AK18: Category # | AL18: LIM | AM18: dd: reference list: PRL: Product Hierarchy Market Category | AN18: Product Hierarchy-Brand | AO18: 1
B19: Requestor Update | L19: 4 | M19: 4 | S19: Product Sub Type | T19: Requestor | U19: dd: reference list: PRODUCT_SETUP_TYPE.XLSX, Setup_Qualifier column | V19: Product Setup | W19: 1 | AB19: Component | AC19: Masterfiles | AD19: free form | AE19: Packaging - Merge with BOM | AF19: 1 | AK19: Dim Details | AL19: Packaging Tech | AM19: autofill | AN19: Alternate Units of Measure | AO19: 1
A20: 2 Total | G20: 12 | L20: 25 | M20: 37 | S20: Product Type | T20: Requestor | U20: dd: reference list: PRODUCT_SETUP_TYPE.XLSX, Setup_Type column | V20: Product Setup | W20: 1 | AB20: Component Description | AC20: Packaging Tech | AD20: free form | AE20: Packaging Components | AF20: 1 | AK20: Dim/Gross Wght Req | AL20: Packaging Tech | AM20: autofill | AN20: Alternate Units of Measure | AO20: 1
A21: 1 | B21: CA Finance Tax | C21: 2 | M21: 2 | S21: Save and Route (button) | T21: Requestor | U21: script button | V21: DTC Product Details | W21: 1 | AB21: Component Pkgs Per Case | AC21: Requestor | AD21: free form | AE21: BOM Setup (VAS) | AF21: 1 | AK21: Gross Wght Dtls | AL21: Packaging Tech | AM21: autofill | AN21: Alternate Units of Measure | AO21: 1
B22: Category Finance - update | D22: 1 | M22: 1 | S22: Stated Net Package Weight (oz) | T22: Nutrition Labeling | U22: calculation | V22: Food Weights in grams/ounces | W22: 1 | AB22: Components Per Variety Pack | AC22: Requestor | AD22: free form | AE22: Variety Pack 0200 BOM Setup | AF22: 1 | AK22: GTIN Prefix | AL22: Masterfiles | AM22: autofill | AN22: UPC, K#, and GTIN Codes | AO22: 1
B23: Data Integrity (DI) - Hierarchy | E23: 1 | M23: 1 | S23: Stated Net Pouch Weight (oz) | T23: Nutrition Labeling | U23: calculation | V23: Food Weights in grams/ounces | W23: 1 | AB23: Conversion Case Code | AC23: Requestor | AD23: free form | AE23: Product Details | AF23: 1 | AK23: Language | AL23: LIM | AM23: dd: reference list: DESCRIPTION_LANGUAGES.XLSX | AN23: Material Description(s) | AO23: 1
B24: Data Integrity (DI) - Review | E24: 1 | M24: 1 | S24: Sub-Type Description | T24: LIM | U24: dd: reference list: PRL: Product Hierarchy Sub-Type | V24: Product Hierarchy-Brand | W24: 1 | AB24: Conversion Date | AC24: Requestor | AD24: date | AE24: Product Details | AF24: 1 | AK24: Location Description | AL24: LIM | AM24: autofill | AN24: Forecast SKU Requirements | AO24: 1
B25: EPM Finance - Update | F25: 2 | M25: 2 | S25: Type Description | T25: LIM | U25: dd: reference list: PRL: Product Hierarchy Type | V25: Product Hierarchy-Brand | W25: 1 | AB25: Country | AC25: Requestor | AD25: dd: reference list: COUNTRY (not in RDL or PRL) | AE25: DTC Product Details | AF25: 1 | AK25: Material Description | AL25: LIM | AM25: autofill | AN25: Material Description(s) | AO25: 1
B26: LIM - Approval/NIF Dashboard | G26: 2 | M26: 2 | S26: Is this Non Sellable FERT WIP | T26: Requestor | U26: dd: YES, NO | V26: Product Determination Questions | W26: 1 | AB26: Country of Origin | AC26: LIM | AD26: dd: reference list: PRL: Country of Origin | AE26: General Product Data | AF26: 1 | AK26: Material Description Length | AL26: LIM | AM26: autofill | AN26: Material Description(s) | AO26: 1
B27: LIM - Forecast Approval | G27: 17 | M27: 17 | R27: 2 | S27: Additional Packaging for Launch | T27: Requestor | U27: dd: reference list: ADDITIONAL_PACKAGING_LAUNCH.XLSX | V27: Special Packaging Requirements | W27: 1 | AB27: Create Forecast Material | AC27: Masterfiles | AD27: button | AE27: Forecast Scripts | AF27: 1 | AK27: Material Group 1 | AL27: Requestor | AM27: dd: reference list: PRL: Material Group 1 | AN27: Product Details | AO27: 1
B28: LIM - Initial Review | G28: 14 | M28: 14 | S28: Brief Product Description | T28: Requestor | U28: free form | V28: Product Setup | W28: 1 | AB28: Create Plant Extension | AC28: Masterfiles | AD28: checkbox | AE28: Plant Extension Selection | AF28: 1 | AK28: Material Prefix | AL28: LIM | AM28: autofill | AN28: Forecast SKU Requirements | AO28: 1
B29: LIM - LIM REPORT | G29: 1 | M29: 1 | S29: Case Count Status | T29: Requestor | U29: dd: ESTIMATED, FINALIZED | V29: Stated Weights/Case Count | W29: 1 | AB29: Data Integrity | AC29: LIM | AD29: dd: user roles | AE29: Person Responsible | AF29: 1 | AK29: Material Segment # | AL29: LIM | AM29: dd: reference list: PRL: Product Hierarchy Market Segment | AN29: Product Hierarchy-Brand | AO29: 1
B30: LIM - Update | G30: 6 | M30: 6 | S30: Choose File | T30: Requestor | U30: dd: directory | V30: Attachments | W30: 1 | AB30: Data Integrity (CA) | AC30: LIM | AD30: dd: user roles | AE30: Person Responsible | AF30: 1 | AK30: Material Segment Description | AL30: LIM | AM30: dd: reference list: PRL: Product Hierarchy Market Segment | AN30: Product Hierarchy-Brand | AO30: 1
B31: LIM Launch - Update | G31: 1 | M31: 1 | S31: Compressed UPC Existing | T31: Requestor | U31: dd: NO, POUCH, PACKAGE, BOTH | V31: Existing Printed Material Codes | W31: 1 | AB31: Defect Group | AC31: R&D Quality | AD31: dd: reference list: PRL: Defect Group | AE31: R & D Quality | AF31: 1 | AK31: MFG Company | AL31: LIM | AM31: dd: reference list: PRL: Manufacturing Company | AN31: Forecast SKU Requirements | AO31: 1
B32: Masterfiles - Approval | H32: 15 | M32: 15 | S32: Country Sold In | T32: LIM | U32: dd: reference list: COUNTRY (not in RDL or PRL) | V32: Forecast SKU Requirements | W32: 1 | AB32: Departure Country | AC32: LIM | AD32: dd: reference list: COUNTRY (not in RDL or PRL) | AE32: Taxes | AF32: 1 | AK32: New Distribution Channel | AL32: Masterfiles | AM32: autofill | AN32: Sales Organization Extension | AO32: 1
B33: Masterfiles - Create Plant Extensions, pricing & BOM's | H33: 15 | M33: 15 | S33: Designated Customer Name | T33: Requestor | U33: dd: reference list: PRL: Designated Customer Name | V33: Product Determination Questions | W33: 1 | AB33: Dieline | AC33: Packaging Tech | AD33: free form | AE33: Packaging Components | AF33: 1 | AK33: New Sales Organization | AL33: Masterfiles | AM33: autofill | AN33: Sales Organization Extension | AO33: 1
B34: Masterfiles - Get Codes | H34: 6 | M34: 6 | S34: External Material Group | T34: LIM | U34: dd: reference list: PRL: External Material Group | V34: Forecast SKU Requirements | W34: 1 | AB34: Display Vehicle | AC34: LIM | AD34: dd: reference list: PRL: Display Vehicle | AE34: General Product Data | AF34: 1 | AK34: Package Size | AL34: LIM | AM34: autofill | AN34: General Product Data | AO34: 1
B35: Masterfiles - Get Codes Forecast | H35: 2 | M35: 2 | S35: Flavor | T35: LIM | U35: dd: reference list: PRL: Flavor | V35: Fields Used for Material Description | W35: 1 | AB35: Distribution Methods | AC35: Masterfiles | AD35: dd: reference list: DISTRIBUTION_METHODS.XLSX | AE35: Review - Derived Values | AF35: 1 | AK35: Package Size UOM | AL35: LIM | AM35: autofill | AN35: General Product Data | AO35: 1
B36: Nutrition Labeling - Update | I36: 20 | M36: 20 | S36: Food Form | T36: LIM | U36: dd: reference list: PRL: Food Form | V36: Fields Used for Material Description | W36: 1 | AB36: DTC Package Price | AC36: Masterfiles | AD36: free form | AE36: DTC Questions | AF36: 1 | AK36: Plant Number List | AL36: Masterfiles | AM36: autofill | AN36: ZMMU_PLANT_Query | AO36: 1
B37: Packaging Tech - Update | J37: 15 | M37: 15 | S37: List Any Existing Knumbers That Will Be Used | T37: Requestor | U37: free form | V37: List Existing K Numbers | W37: 1 | AB37: EPM Finance | AC37: LIM | AD37: dd: user roles | AE37: Person Responsible | AF37: 1 | AK37: Pouch Size | AL37: LIM | AM37: autofill | AN37: General Product Data | AO37: 1
B38: R&D Quality - Update | K38: 4 | M38: 4 | S38: List Existing Export UPC Codes | T38: Requestor | U38: free form | V38: Product Determination Questions | W38: 1 | AB38: Estimated Standard Cost | AC38: LIM | AD38: free form | AE38: Forecast SKU Requirements | AF38: 1 | AK38: Pouch Size UOM | AL38: LIM | AM38: autofill | AN38: General Product Data | AO38: 1
B39: Requestor - Project Initiation | H39: 1 | L39: 21 | M39: 22 | S39: List Existing Private UPCs | T39: Requestor | U39: free form | V39: Product Determination Questions | W39: 1 | AB39: FERT Type | AC39: Requestor | AD39: dd: reference list: PRL: FERT Type | AE39: Product Details | AF39: 1 | AK39: Pricing Validity Date | AL39: Requestor | AM39: autofill | AN39: Product Details | AO39: 1
B40: Requestor - Req Launch DTC | L40: 3 | M40: 3 | S40: List UPC Codes If Already Assigned | T40: Requestor | U40: free form | V40: Existing Printed Material Codes | W40: 1 | AB40: Final Red K List Price (cs) | AC40: Category Finance | AD40: free form | AE40: Pricing | AF40: 1 | AK40: Pringles Can Size | AL40: Packaging Tech | AM40: autofill | AN40: Packaging Details | AO40: 1
B41: Requestor Update | L41: 38 | M41: 38 | S41: Location | T41: LIM | U41: dd: reference list: ZMMU table (not in RDL or PRL) | V41: Forecast SKU Requirements | W41: 1 | AB41: Food Count (Bars, Waffles, PT, Shakes, RKT) | AC41: Requestor | AD41: free form | AE41: Values used to determine material description | AF41: 1 | AK41: Promo Short Description | AL41: Requestor | AM41: dd: reference list: PRL: Promotion | AN41: Promotion | AO41: 1
A42: 1 Total | C42: 2 | D42: 1 | E42: 2 | F42: 2 | G42: 41 | H42: 39 | I42: 20 | J42: 15 | K42: 4 | L42: 62 | M42: 188 | S42: Material Group | T42: LIM | U42: dd: reference list: PRL: Material Group | V42: Forecast SKU Requirements | W42: 1 | AB42: Forecast Entry Options | AC42: LIM | AD42: radio button: DEFAULTS, ESTIMATED, ACTUALS | AE42: Alternate Units of Measure | AF42: 1 | AK42: Remarket Date | AL42: Requestor | AM42: autofill | AN42: Product Details | AO42: 1
A43: 0 | B43: LIM - Forecast Approval | G43: 23 | M43: 23 | S43: Material Prefix Description | T43: Requestor | U43: dd: reference list: MATERIAL_PREFIX.XLSX | V43: Other UPC Requirements | W43: 1 | AB43: Generate Material Description | AC43: LIM | AD43: button | AE43: Material Description(s) | AF43: 1 | AK43: Requestor | AL43: Requestor | AM43: dd: user roles | AN43: Person Responsible | AO43: 1
B44: LIM - Update | G44: 4 | M44: 4 | S44: Package K Number | T44: Requestor | U44: free form | V44: Existing Printed Material Codes | W44: 1 | AB44: Grams per piece | AC44: Nutrition Labeling | AD44: free form | AE44: Food Weights | AF44: 1 | AK44: Requestor Date | AL44: Requestor | AM44: autofill | AN44: Requestor Initiate | AO44: 1
...

Sheet marketing questions
C1: These are the questions that Marketing has on their end around Brand and Type:
A2: new Brand | B2: If this is a new Brand requiring a separate Profit Center and separate P&L from existing Brands, then it requires a new Brand, which could take 3 weeks to create. Contact Juliana Hurtado and Christa Clapper. | C2: - Is this a new Brand, requiring a separate Profit Center and separate P&L from existing Brands?
C3: o Yes - If so, it requires a different or new Brand, which could take 3 weeks to create. Contact Juliana Hurtado and Christa Clapper.
A4: new Planning in TPM, or new Type | B4: If this item will be planned in TPM separately from existing products, then it requires a new Type, which could take 3 weeks to create. Contact Supply Chain Data Governance at SCDataGov@kellanova.com. | C4: o No - Will this be planned in TPM separately from existing products?
C5: o Yes - If so, it requires a different or new Type, which could take 3 weeks to create. Contact Supply Chain Data Governance at SCDataGov@kellanova.com.
A6: new Food Form | B6: If this item is a new Food Form that will fall under an existing Brand, then it requires a new Type, which could take 3 weeks to create. Contact Supply Chain Data Governance at SCDataGov@kellanova.com. | C6: o No - Is this a new Food Form that will fall under an existing Brand?
C7: § Yes - It requires a different or new Type, which could take 3 weeks to create. Contact Supply Chain Data Governance at SCDataGov@kellanova.com.
A8: new Size | B8: If this item is a new Size, then it may require a new Type, which could take 3 weeks to create. Contact Commercial Enablement. | C8: § No - Is this a new Size?
C9: § Yes - It may require a different or new Type, which could take 3 weeks to create. - contact Commercial Enablement
A10: new Package Price, or new Price | B10: If this item is a new Package Price, then it may require a new Type, which could take 3 weeks to create. Contact Commercial Enablement. | C10: § No - Is this a new package price?
C11: § Yes - It may require new Type. - contact Commercial Enablement
A12: new Sub Brand, or new Sub-Brand | B12: If this item is a new Sub Brand, then submit a KNA Request Product Value form in Evolve. | C12: § No - Is this a new Sub Brand?
C13: § Yes - submit a KNA Request Product Value form in Evolve
A14: Brand | B14: If this item is On The Go/Convenience Snack Packs, then ensure selection of Brand name during Requestor Update task includes OTG (EX: Caddies Cheez-It OTG). | C14: § No - OTG (On The Go) is usually in a different Brand hierarchy than core. Is this an OTG item?
C15: § Yes - Ensure selection of Brand name during Requestor Update task includes OTG (example: Caddies Cheez-It OTG)
C16: § No - Ensure selection of Brand name during Requestor Update task does not include OTG
C19: Is this a CSP (OTG) item?
A20: Brand | B20: If this item is On The Go/Convenience Snack Packs, then ensure selection of Brand name during Requestor Update task includes OTG (EX: Caddies Cheez-It OTG). | C20: § Yes - Ensure selection of Brand name during Requestor Update task includes OTG (example: Caddies Cheez-It OTG)
C21: § No - Ensure selection of Brand name during Requestor Update task does not include OTG
A22: new Brand | B22: If this is a new Brand requiring a separate Profit Center and separate P&L from existing Brands, then it requires a new Brand, which could take 3 weeks to create. Contact Juliana Hurtado and Christa Clapper. | C22: Is this a new Brand requiring a separate Profit Center and separate P&L from existing Brands?
C23: o Yes - If so, it requires a different or new Brand, which could take 3 weeks to create. Contact Juliana Hurtado and Christa Clapper.
A24: new Planning in TPM, or new Type | B24: If this item will be planned in TPM separately from existing products, then it requires a new Type, which could take 3 weeks to create. Contact Supply Chain Data Governance at SCDataGov@kellanova.com. | C24: o No - Will this be planned in TPM separately from existing products? Refer to the PH Report to review where current items are assigned.
C25: o Yes - If so, it requires a different or new Type, which could take 3 weeks to create. Contact Supply Chain Data Governance at SCDataGov@kellanova.com.
A26: new Food Form | B26: If this item is a new Food Form that will fall under an existing Brand, then it requires a new Type, which could take 3 weeks to create. Contact Supply Chain Data Governance at SCDataGov@kellanova.com. | C26: o No - Is this a new Food Form that will fall under an existing Brand?
C27: § Yes - It requires a different or new Type, which could take 3 weeks to create. Contact Supply Chain Data Governance at SCDataGov@kellanova.com.
A28: new Size | B28: If this item is a new Size, then it may require a new Type, which could take 3 weeks to create. Contact Commercial Enablement. | C28: § No - Is this a new Size?
C29: § Yes - It may require a different or new Type, which could take 3 weeks to create. - contact Commercial Enablement
